
███████╗██╗   ██╗██╗██╗       ██╗     ██╗███╗   ███╗██╗████████╗███████╗██████╗ 
██╔════╝██║   ██║██║██║       ██║     ██║████╗ ████║██║╚══██╔══╝██╔════╝██╔══██╗
█████╗  ██║   ██║██║██║       ██║     ██║██╔████╔██║██║   ██║   █████╗  ██████╔╝
██╔══╝  ╚██╗ ██╔╝██║██║       ██║     ██║██║╚██╔╝██║██║   ██║   ██╔══╝  ██╔══██╗
███████╗ ╚████╔╝ ██║███████╗  ███████╗██║██║ ╚═╝ ██║██║   ██║   ███████╗██║  ██║
╚══════╝  ╚═══╝  ╚═╝╚══════╝  ╚══════╝╚═╝╚═╝     ╚═╝╚═╝   ╚═╝   ╚══════╝╚═╝  ╚═╝
                by bitbrute  ~  limit devices on your network :3
                                    v1.5.0


OK   interface: wlan0
OK   gateway ip: 192.168.1.1
OK   gateway mac: 9c:a2:f4:96:6a:ec
OK   netmask: 255.255.255.0

OK   flushed network settings

type help or ? to show command information.
(Main) >>> Traceback (most recent call last):
  File "/usr/local/bin/evillimiter", line 33, in <module>
    sys.exit(load_entry_point('evillimiter==1.5.0', 'console_scripts', 'evillimiter')())
             ^^^^^^^^^^^^^^^^^^^^^^^^^^^^^^^^^^^^^^^^^^^^^^^^^^^^^^^^^^^^^^^^^^^^^^^^^^
  File "/usr/local/lib/python3.11/dist-packages/evillimiter-1.5.0-py3.11.egg/evillimiter/evillimiter.py", line 175, in run
    menu.start()
  File "/usr/local/lib/python3.11/dist-packages/evillimiter-1.5.0-py3.11.egg/evillimiter/menus/menu.py", line 35, in start
    command = IO.input(self.prompt)
              ^^^^^^^^^^^^^^^^^^^^^
  File "/usr/local/lib/python3.11/dist-packages/evillimiter-1.5.0-py3.11.egg/evillimiter/console/io.py", line 64, in input
    return input(prompt)
           ^^^^^^^^^^^^^
OSError: [Errno 9] Bad file descriptor
